Workbook
Name AGRICULTURE: '.'!$AC$2:$AC$5
Name AGRICULTURE: PARAMETRAGE!$AC$2:$AC$5
Name ALIBORI: '.'!$P$2:$P$7
Name ALIBORI: PARAMETRAGE!$P$2:$P$7
Name Alimentation: PARAMETRAGE!$AD$4
Name ARTISANAT: '.'!$AE$2:$AE$9
Name ARTISANAT: PARAMETRAGE!$AE$2:$AE$9
Name Assistance: PARAMETRAGE!$AF$3
Name ATACORA: '.'!$Q$2:$Q$10
Name ATACORA: PARAMETRAGE!$Q$2:$Q$10
Name ATLANTIQUE: '.'!$R$2:$R$9
Name ATLANTIQUE: PARAMETRAGE!$R$2:$R$9
Name Auto_école: PARAMETRAGE!$AF$5
Name Autre: '.'!$AM$1
Name Autre: PARAMETRAGE!$AM$1
Name Autres_revenus: '.'!$CP$1:$CP$6
Name Autres_revenus: PARAMETRAGE!$CP$1:$CP$6
Name Boffa: PARAMETRAGE!$Q$9:$Q$16
Name BOKÉ: PARAMETRAGE!$Q$2:$Q$6
Name Boké_: PARAMETRAGE!$R$9:$R$18
Name BORGOU: '.'!$S$2:$S$9
Name BORGOU: PARAMETRAGE!$S$2:$S$9
Name Charges_exploitation: '.'!$K$1:$K$26
Name Charges_exploitation: PARAMETRAGE!$K$1:$K$26
Name Coiffure: PARAMETRAGE!$AE$4
Name COLLINES: '.'!$T$2:$T$7
Name COLLINES: PARAMETRAGE!$T$2:$T$7
Name COMMERCE: '.'!$AD$2:$AD$8
Name COMMERCE: PARAMETRAGE!$AD$2:$AD$8
Name Commercialisation: '.'!$AL$2:$AL$15
Name Commercialisation: PARAMETRAGE!$AL$2:$AL$16
Name CONAKRY: PARAMETRAGE!$P$2
Name Cordonnerie: PARAMETRAGE!$AE$7
Name Cosmétique: PARAMETRAGE!$AD$5
Name COUFFO: '.'!$U$2:$U$7
Name COUFFO: PARAMETRAGE!$U$2:$U$7
Name Département: '.'!$O$1:$O$12
Name Département: PARAMETRAGE!$O$1:$O$12
Name Divers_Service: PARAMETRAGE!$AF$4
Name DONGA: '.'!$V$2:$V$5
Name DONGA: PARAMETRAGE!$V$2:$V$5
Name École___Collège: PARAMETRAGE!$AF$6
Name Fabrication: PARAMETRAGE!$AG$2
Name FARANAH: PARAMETRAGE!$U$2:$U$5
Name FIVE: PARAMETRAGE!$ED$1:$ED$6
Name Formation: PARAMETRAGE!$AF$2
Name FOUR: PARAMETRAGE!$EC$1:$EC$5
Name Habillement: PARAMETRAGE!$AD$2
Name Historique: '.'!$L$8:$L$14
Name Historique: PARAMETRAGE!$L$8:$L$14
Name INDUSTRIE: '.'!$AG$2:$AG$3
Name INDUSTRIE: PARAMETRAGE!$AG$2:$AG$3
Name KANKAN: PARAMETRAGE!$V$2:$V$5
Name KINDIA: PARAMETRAGE!$R$2:$R$6
Name LABÉ: PARAMETRAGE!$T$2:$T$6
Name LITTORAL: '.'!$W$2
Name LITTORAL: PARAMETRAGE!$W$2
Name Maçonnerie: PARAMETRAGE!$AE$6
Name MAMOU: PARAMETRAGE!$S$2:$S$4
Name Mécanique: PARAMETRAGE!$AE$5

Sheet Modele

Sheet .
A1: 1 | B1: L’emprunteur fait partie de l’élite des producteurs; il se démarque par ses capacités de gestionnaire et une bonne solidité financière. Il maîtrise bien ses outils de production et est en mesure de donner à l’agent de crédit une information pertinente dans les délais requis. Il respecte ses engagements personnels et financiers. Bien qu’il n’existe aucune situation où les risques de défaut sont nuls, cette catégorie d’emprunteurs pourra disposer de conditions de crédit et d’encadrement favorables. | C1: Fonds de roulement | F1: Cout de production | G1: Chiffre d'affaire | K1: Loyer | L1: Excellent | M1: Sous-sous-secteur d'activité | N1: 1 | O1: Alibori | P1: ALIBORI | Q1: ATACORA | R1: ATLANTIQUE | S1: BORGOU | T1: COLLINES | U1: COUFFO | V1: DONGA | W1: LITTORAL | X1: MONO | Y1: OUÉMÉ | Z1: PLATEAU | AA1: ZOU | AC1: AGRICULTURE | AD1: COMMERCE | AE1: ARTISANAT | AF1: SERVICE | AG1: INDUSTRIE | AH1: Autre | AI1: Production_animale | AJ1: Production_végétale | AK1: Transformation | AL1: Commercialisation | AM1: Autre | AO1: Ratios | AV1: ='5. RESULTAT'!K36 -> Calculs | AX1: ='5. RESULTAT'!M36 -> Résultats | AY1: Excellent | AZ1: Bon ratio | BA1: Passable | BB1: insuffisant | BC1: Médiocre | BF1: =CONCATENATE("Le crédit dépasse le besoin réel de ",(BF4),"%") -> Le crédit dépasse le besoin réel de -67,49% | CM1: Prélèvement | CN1: =IF('5. RESULTAT'!D16="Prélèvement de l'exploitant",'5. RESULTAT'!K16,0) -> 0 | CP1: Revenus nets issus d'autres activités commerciales
A2: 2 | B2: Il est évident que l’emprunteur ayant une cote de risque basse constitue aussi pour la compétition une cible de choix; l’agent de crédit devra donc éviter de négliger cette clientèle. Avec cette clientèle, l'agent de crédit devra être proactif et orienté sur le maintien d’une bonne relation d’affaires et le service-conseil. | C2: Achat d'intrants | E2: Production végétale | F2: ='2. PROD'!I16 -> 922680000 | G2: ='2. PROD'!I24 -> 1700000000 | K2: Salaires employés | L2: Très bien | M2: Agrumes | N2: 2 | O2: Atacora | P2: Banikoara | Q2: Boukoumbé | R2: Abomey-Calavi | S2: Bembéréké | T2: Bantè | U2: Aplahoué | V2: Bassila | W2: Cotonou | X2: Athiémé | Y2: Adjarra | Z2: Ifangni | AA2: Abomey | AC2: Production_animale | AD2: Habillement | AE2: Menuiserie | AF2: Formation | AG2: Fabrication | AI2: Bovin | AJ2: Agrumes | AK2: Agrumes | AL2: Agrumes | AO2: Niveau de participation R ≤ 65 % | AQ2: Montant du crédit proposé | AV2: ='5. RESULTAT'!K37 -> 300000000 | AX2: ='5. RESULTAT'!M37 -> 0.32513981 | AY2: Excellent ratio. Le niveau de participation de financement est très faible. | AZ2: Bon ratio. Le niveau de participation de financement est acceptable. | BA2: Ratio passable. Le niveau de participation de financement est au seuil de la norme indiquée. | BB2: Le niveau de participation de financement dépasse la limite sugérée. | BC2: Attention, le niveau de participation de financement dépasse les dépenses prévues. | BE2: =IF('1. DEMANDE'!I54="Investissement",'3. BILAN'!J50,'3. BILAN'!J60) -> 922680000 | BF2: =IF('8. PROPOSITION'!M12>BE2,BF1,IF('8. PROPOSITION'!M12=BE2,"Le crédit couvre bien le besoin réel.","Attention, le crédit ne couvre pas le besoin réel.")) -> Attention, le crédit ne couvre pas le besoin réel. | BG2: =IF(AX2<=20%,AY2,IF(AND(AX2>20%,AX2<=50%),AZ2,IF(AND(AX2>50%,AX2<=65%),BA2,IF(AND(AX2>65%,AX2<=100%),BB2,IF(AX2>100%,BC2,""))))) -> Bon ratio. Le niveau de participation de financement est acceptable. | BH2: =CONCATENATE(BG2," ",BF2) -> Bon ratio. Le niveau de participation de financement est acceptable. Attention, le crédit ne couvre pas le besoin réel. | BI2: =IF('8. PROPOSITION'!M12="","",IF(BE2<0,"Attention ! Ce client n'a de besoin réel identifié - veuillez revoir les analyses",BH2)) -> Bon ratio. Le niveau de participation de financement est acceptable. Attention, le crédit ne couvre pas le besoin réel. | CM2: Prélèvement | CN2: =IF('5. RESULTAT'!D17="Prélèvement de l'exploitant",'5. RESULTAT'!K17,0) -> 0 | CP2: Salaires net (après déduction des engagements)
A3: 3 | B3: L’emprunteur faisant partie de cette catégorie ne constitue pas un risque dans la mesure où il est bien encadré. Sa maîtrise des outils de production et de gestion est bonne mais pourrait être améliorée. Puisque la majorité des emprunteurs font partie de cette catégorie, l’agent de crédit doit user de son jugement, s’appuyer sur son expérience et faire preuve de discernement afin de bien conseiller cette clientèle et appuyer son développement. | C3: Achats de petits outillages | E3: Production animale | F3: =ANIMAL!J24 -> 0 | G3: =ANIMAL!J32 -> 0 | K3: Fourniture de bureau | L3: Bien | M3: Anacarde | N3: 3 | O3: Atlantique | P3: Gogounou | Q3: Cobly | R3: Allada | S3: Kalalé | T3: Dassa-Zoumè | U3: Djakotomey | V3: Copargo | X3: Bopa | Y3: Adjohoun | Z3: Adja-Ouèrè | AA3: Agbangnizoun | AC3: Production_végétale | AD3: Restauration | AE3: Soudure | AF3: Assistance | AG3: Autre | AI3: Aquaculture | AJ3: Anacarde | AK3: Anacarde | AL3: Anacarde | AQ3: Total Dépenses d'exploitation | AV3: ='5. RESULTAT'!K38 -> 922680000 | AY3: <=20% | AZ3: >20 et <=50 | BA3: >50 et <=65 | BB3: >65 et <=100 | BC3: >100 | BF3: =(('8. PROPOSITION'!M12/BE2)-1)*100 -> -67.486019 | CM3: Prélèvement | CN3: =IF('5. RESULTAT'!D18="Prélèvement de l'exploitant",'5. RESULTAT'!K18,0) -> 0 | CP3: Prélèvement de l'exploitant
A4: 4 | B4: Il peut s’agir d’un emprunteur de longue date qui a connu une situation adverse avec qui il faut opérer un redressement ou d’un emprunteur qui est financièrement plus serré, mais qui démontre des aptitudes pour progresser vers les catégories supérieures ou qui est en expansion rapide. Bien que non obligatoire, le support d’un conseiller technique et de gestion pourrait être suggéré. Appuyez-vous sur les commentaires relatifs aux Ratios de décision pour valider votre recommandation. | C4: Investissement | E4: Transformation | F4: =TRFM1!J29+TRFM2!J29+TRFM3!J29 -> 0 | G4: =TRFM1!J37+TRFM2!J37+TRFM3!J37 -> 0 | K4: Publicité et promotion | L4: Passable | M4: Ananas | N4: 4 | O4: Borgou | P4: Kandi | Q4: Kérou | R4: Kpomassè | S4: N'Dali | T4: Glazoué | U4: Dogbo | V4: Djougou | X4: Comè | Y4: Aguégués | Z4: Kétou | AA4: Bohicon | AC4: Transformation | AD4: Alimentation | AE4: Coiffure | AF4: Service divers | AI4: Aviculture | AJ4: Ananas | AK4: Ananas | AL4: Ananas | AO4: Couverture de l'échéance R ≥ 1,5 | AQ4: Capacité de remboursement | AV4: ='5. RESULTAT'!K39 -> 2.6050533e+08 | AX4: ='5. RESULTAT'!M39 -> 1.439256 | AY4: >4 | AZ4: <=4 et >=2 | BA4: <2 et >=1,5 | BB4: <1,5 et >=1 | BC4: <1 | BF4: =ROUNDUP(BF3,2) -> -67.49 | BI4: =IF('8. PROPOSITION'!M12="","",IF('5. RESULTAT'!K32<0,"Attention ! La capacité de rembourssement est négative - veuillez échanger avec le client",BG5)) -> La couverture de l'échéance est acceptable mais trop juste. Le risque d'impayé est à prendre en compte. | CM4: Prélèvement | CN4: =IF('5. RESULTAT'!D19="Prélèvement de l'exploitant",'5. RESULTAT'!K19,0) -> 0 | CP4: Contribution d'autres personnes de la famille
A5: 5 | B5: En tant que professionnel, l’agent de crédit doit traiter tous les emprunteurs avec considération et professionnalisme. Avec les emprunteurs de cette catégorie, il devra donc considérer les demandes visant à améliorer la situation des emprunteurs tout en portant un suivi attentif à son dossier de crédit parce que celui-ci n’a pas une grande marge de manœuvre en cas de difficulté. Puisque les emprunteurs dans cette catégorie ne pourront obtenir des crédits importants, le rôle de l’agent de crédit sera donc de les conseiller afin qu’ils utilisent leur crédit judicieusement, qu’ils respectent leurs échéances et qu’ils améliorent leur maîtrise de la production. Ceci afin de pouvoir améliorer leur cote de risque et l’accès au financement. Les crédits devraient tous être adéquatement garantis et/ou avalisés. Toute autre mesure d’atténuation de risque telle que l’assurance agricole (si cela existe) devrait être obligatoire. | C5: Autre | E5: Commercialisation | F5: =COMM!J24 -> 0 | G5: =COMM!J32 -> 0 | K5: Téléphone / Internet | L5: Faible | M5: Aquaculture | N5: 5 | O5: Collines | P5: Karimama | Q5: Kouandé | R5: Ouidah | S5: Nikki | T5: Ouèssè | U5: Klouékanmè | V5: Ouaké | X5: Grand-Popo | Y5: Akpro-Missérété | Z5: Pobè | AA5: Covè | AC5: Commercialisation | AD5: Cosmétique | AE5: Mécanique | AF5: Auto-école | AI5: Caprin | AJ5: Arachide | AK5: Arachide | AL5: Arachide | AQ5: Service de la dette | AV5: ='5. RESULTAT'!K40 -> 181000000 | AY5: Excellent ratio. La couverture de l'échéance ou de service de la dette est confortable. | AZ5: Bon ratio. La couverture de l'échéance ou de service de la dette est bonne. | BA5: Ratio acceptable. La couverture de l'échéance ou de service de la dette est rassurante. | BB5: La couverture de l'échéance est acceptable mais trop juste. Le risque d'impayé est à prendre en compte. | BC5: Ratio trop faible - L'échéance ou le service de la dette n'est pas couvert. Forte probabilité de défaut. | BG5: =IF(AX4>4,AY5,IF(AND(AX4<=4,AX4>=2),AZ5,IF(AND(AX4<2,AX4>=1.5),BA5,IF(AND(AX4<1.5,AX4>=1),BB5,IF(AX4<1,BC5,""))))) -> La couverture de l'échéance est acceptable mais trop juste. Le risque d'impayé est à prendre en compte. | BI5: =IF('5. RESULTAT'!K33<0,"Attention ! La capacité de rembourssement est négative - veuillez échanger avec le client",IF('8. PROPOSITION'!M13="","",BG6)) | CM5: Prélèvement | CN5: =IF('5. RESULTAT'!D20="Prélèvement de l'exploitant",'5. RESULTAT'!K20,0) -> 0 | CP5: Revenus nets issus de la location (biens immobiliers et/matériels)
A6: 6 | B6: L’emprunteur (client) : - n'a pas d'expérience avérée dans le domaine - a de fortes probabilités d’être en défaut à court terme; - n’a pas de marge de manœuvre; - emprunte au-delà de sa capacité de remboursement. - a un mauvais historique de crédit; - a dans le passé, refusé certainement de collaborer afin de trouver des solutions à ses problèmes. Appuyez-vous sur les commentaires associés aux ratios de décision avant de valider le rejet de cette demande de crédit. | F6: =IF(OR('1. DEMANDE'!G30="COMMERCE",'1. DEMANDE'!G30="SERVICE"),F5,IF('1. DEMANDE'!R30="Production_végétale",F2,IF('1. DEMANDE'!R30="Production_animale",F3,IF(OR('1. DEMANDE'!R30="Transformation",'1. DEMANDE'!G30="ARTISANAT",'1. DEMANDE'!G30="INDUSTRIE"),F4,IF('1. DEMANDE'!R30="Commercialisation",F5,0))))) -> 922680000 | G6: =IF(OR('1. DEMANDE'!G30="COMMERCE",'1. DEMANDE'!G30="SERVICE"),G5,IF('1. DEMANDE'!R30="Production_végétale",G2,IF('1. DEMANDE'!R30="Production_animale",G3,IF(OR('1. DEMANDE'!R30="Transformation",'1. DEMANDE'!G30="ARTISANAT",'1. DEMANDE'!G30="INDUSTRIE"),G4,IF('1. DEMANDE'!R30="Commercialisation",G5,0))))) -> 1700000000 | K6: Communication | L6: Très faible | M6: Pêche | N6: 6 | O6: Couffo | P6: Malanville | Q6: Matéri | R6: Sô-Ava | S6: Parakou | T6: Savalou | U6: Lalo | X6: Houéyogbé | Y6: Avrankou | Z6: Sakété | AA6: Djidja | AD6: Mercerie | AE6: Maçonnerie | AF6: École - Collège | AI6: Ovin | AJ6: Coton | AK6: Coton | AL6: Igname | AO6: Ratio de fonds de roulement R ≥ 1,5 | AQ6: Actif à court terme | AV6: ='5. RESULTAT'!K41 -> 56000000 | AX6: ='5. RESULTAT'!M41 -> 2.8 | AY6: >4 | AZ6: <=4 et >=2 | BA6: <2 et >=1,5 | BB6: <1,5 et >=1 | BC6: <1 | BI6: =IF('8. PROPOSITION'!M12="","",BG7) -> Bon ratio. Les actifs à court terme surpassent les dettes à moins d'un an et dégagent un surplus important. | CM6: Prélèvement | CN6: =IF('5. RESULTAT'!D21="Prélèvement de l'exploitant",'5. RESULTAT'!K21,0) -> 0 | CP6: Autres sources de revenus
K7: Électricité | M7: Arachide | N7: 7 | O7: Donga | P7: Segbana | Q7: Natitingou | R7: Toffo | S7: Pèrèrè | T7: Savè | U7: Toviklin | X7: Lokossa | Y7: Bonou | AA7: Ouinhi | AD7: Vaisselle -Émaux | AE7: Cordonnerie | AF7: Autre | AI7: Pêche | AJ7: Igname | AK7: Igname | AL7: Maïs | AQ7: Passif à court terme | AV7: ='5. RESULTAT'!K42 -> 20000000 | AY7: Excellent ratio. Il existe un fonds de roulement conséquent permettant de faire tourner l'activité. | AZ7: Bon ratio. Les actifs à court terme surpassent les dettes à moins d'un an et dégagent un surplus important. | BA7: Bon ratio. Les actifs à court terme surpassent les dettes à moins d'un an et dégagent un surplus important. | BB7: Ratio passable. Les actifs à court terme surpassent légèrement les dettes à moins d'un an. Risque d'insuffisance du fonds de roulement. | BC7: Ratio trop faible - Fonds de roulement négatif. Nécessité de renforcer l'exploitation. | BG7: =IF(AX6>4,AY7,IF(AND(AX6<=4,AX6>=2),AZ7,IF(AND(AX6<2,AX6>=1.5),BA7,IF(AND(AX6<1.5,AX6>=1),BB7,IF(AX6<1,BC7,""))))) -> Bon ratio. Les actifs à court terme surpassent les dettes à moins d'un an et dégagent un surplus important. | BI7: =IF('5. RESULTAT'!K35<0,"Attention ! La capacité de rembourssement est négative - veuillez échanger avec le client",IF('8. PROPOSITION'!M15="","",BG8)) | CM7: Prélèvement | CN7: =IF('5. RESULTAT'!D22="Prélèvement de l'exploitant",'5. RESULTAT'!K22,0) -> 0
K8: Eau | L8: Nouveau Client | M8: Aviculture | O8: Littoral | Q8: Pehonko | R8: Tori-Bossito | S8: Sinendé | Y8: Dangbo | AA8: Za-Kpota | AD8: Autre | AE8: Coiffure | AI8: Pisciculture | AJ8: Maïs | AK8: Maïs | AL8: Mangue | AO8: Ratio de solvabilité R ≤ 0,5 | AQ8: Dettes totales | AV8: ='5. RESULTAT'!K43 -> 20000000 | AX8: ='5. RESULTAT'!M43 -> 0.017050298 | AY8: <0,1 | AZ8: >=0,1 et<=0,5 | BA8: >=0,1 et<=0,5 | BB8: >=0,5 et<=1 | BC8: >1 | CM8: Prélèvement | CN8: =IF('5. RESULTAT'!D23="Prélèvement de l'exploitant",'5. RESULTAT'!K23,0) -> 0
K9: Assurances | L9: Excellent | M9: Coton | O9: Mono | Q9: Tanguiéta | R9: Zè | S9: Tchaourou | Y9: Porto-Novo | AA9: Zagnanado | AE9: Autre | AI9: Autre | AJ9: Mangue | AK9: Mangue | AL9: Manioc | AQ9: Fonds propres | AV9: ='5. RESULTAT'!K44 -> 1173000000 | AY9: Excellent ratio de solvabilité. Les dettes de l'entreprise sont très faibles par rapport aux fonds propres | AZ9: La norme de solvabilité est respectée. Les dettes de l'entreprise sont faibles par rapport aux fonds propres | BB9: La norme de solvabilité n'est pas respectée. Les dettes de l'entreprise sont élevés et s'étendent vers le niveau de fonds propres | BC9: Les dettes de l'entreprise sont très élevées et dépassent le niveau de fonds propres. L'entreprise n'est pas solvable. | BF9: =IF('3. BILAN'!I37<0,"Attention, les fonds propres sont négatifs. Il faut échanger avec le client.",'.'!BG9) -> Excellent ratio de solvabilité. Les dettes de l'entreprise sont très faibles par rapport aux fonds propres | BG9: =IF(AX8<0.1,AY9,IF(AND(AX8>=0.1,AX8<=0.5),AZ9,IF(AND(AX8>0.5,AX8<=1),BB9,IF(AX8>1,BC9,"")))) -> Excellent ratio de solvabilité. Les dettes de l'entreprise sont très faibles par rapport aux fonds propres | BI9: =IF('8. PROPOSITION'!M12="","",BF9) -> Excellent ratio de solvabilité. Les dettes de l'entreprise sont très faibles par rapport aux fonds propres | CM9: Prélèvement | CN9: =IF('5. RESULTAT'!D24="Prélèvement de l'exploitant",'5. RESULTAT'!K24,0) -> 0
K10: Frais de transport | L10: Très bien | M10: Bovin/Ovin/Caprin | O10: Ouémé | Q10: Toucountouna | Y10: Sèmè-Kpodji | AA10: Zogbodomey | AJ10: Manioc | AK10: Manioc | AL10: Maraîchage | AO10: Ratio de liquidité immédiate R ≥ 1 | AQ10: Trésorerie disponible | AV10: ='5. RESULTAT'!K45 -> 36000000 | AX10: ='5. RESULTAT'!M45 -> 1.8 | AY10: >4 | AZ10: <=4 et >=2 | BA10: <2 et >=1 | BB10: <1 et >=0,75 | BC10: <075 | CM10: Prélèvement | CN10: =IF('5. RESULTAT'!D25="Prélèvement de l'exploitant",'5. RESULTAT'!K25,0) -> 0
K11: Entretien et réparation | L11: Bien | M11: Igname | O11: Plateau | AJ11: Maraîchage | AK11: Niébé | AL11: Niébé | AQ11: Passif à court terme | AV11: ='5. RESULTAT'!K46 -> 20000000 | AY11: Excellent ratio. Les "dettes à moins d'un an" peuvent être réglées facilement. | AZ11: Très bon ratio. La trésorerie et les créances sont assez importantes pour régler les dettes à moins d'un an. | BA11: Ratio respectant la norme. Les dettes à moins d'un an seront réglées. | BB11: Ratio ne respectant pas la norme. Des difficultés subsistent pour le règlement des dettes à moins d'un an. | BC11: Ratio hors norme. L'entreprise peut être en difficulté et doit compter sur la vente de ses stocks pour régler ses dettes à court terme. | BG11: =IF(AX10>4,AY11,IF(AND(AX10<=4,AX10>=2),AZ11,IF(AND(AX10<2,AX10>=1),BA11,IF(AND(AX10<1,AX10>=0.75),BB11,IF(AX10<0.75,BC11,""))))) -> Ratio respectant la norme. Les dettes à moins d'un an seront réglées. | BI11: =IF('8. PROPOSITION'!M12="","",BG11) -> Ratio respectant la norme. Les dettes à moins d'un an seront réglées. | CM11: Prélèvement | CN11: =IF('5. RESULTAT'!D26="Prélèvement de l'exploitant",'5. RESULTAT'!K26,0) -> 0
B12: Critères | C12: Cote de risque (1 à 6) | D12: Zone de risque maximun (proche de 6) | F12: Zone de risque maximun (proche de 6) | G12: Zone de risque maximun (proche de 6) | H12: Zone de risque maximun (proche de 6) | I12: Zone de risque maximun (proche de 6) | K12: Carburant | L12: Passable | M12: Maïs | O12: Zou | AJ12: Niébé | AK12: Palmier à huile | AL12: Riz | AO12: Ratio d'endettement R < 65 % | AQ12: Dettes totales + Crédit proposé | AV12: ='5. RESULTAT'!K47 -> 320000000 | AX12: ='5. RESULTAT'!M47 -> 0.21433356 | AY12: <10 | AZ12: >=10<25 | BA12: >=25<75 | BB12: >75<=100 | BC12: >100 | CM12: Total | CN12: =CN1+CN2+CN3+CN4+CN5+CN6+CN7+CN8+CN9+CN10+CN11 -> 0
B13: ='7. RISQUE'!B13 -> A. Direction Compétences, expériences, qualité morale, stabilité sociale.. | C13: =IF('7. RISQUE'!$B$23="Veuillez noter tous les critères de risques !",0,'7. RISQUE'!H13) -> 1 | D13: 6 | E13: Zone de risque maximun (proche de 6) | F13: 4 | G13: 3 | H13: 2 | I13: 1 | K13: Frais douane | L13: Faible | M13: Manguier | T13: ='8. PROPOSITION'!M12 -> 300000000 | U13: =T13/'8. PROPOSITION'!M20 -> 100000000 | AJ13: Palmier à huile | AK13: Riz | AL13: Soja | AQ13: Actif total + Crédit proposé | AV13: ='5. RESULTAT'!K48 -> 1493000000 | AY13: Niveau d'endettement très faible pour l'entreprise. Elle peut profiter des crédits productifs pour sa croissance. | AZ13: Niveau d'endettement faible pour l'entreprise. Elle possède une bonne marge pour s'endetter davantage. | BA13: Niveau d'endettement acceptable. | BB13: Niveau d'endettement très élevé pour l'entreprise. | BC13: Surendettement de l'entreprise. Le nouveau crédit risque de plonger davantage l'entreprise | BG13: =IF(AX12<10%,AY13,IF(AND(AX12>=10%,AX12<25%),AZ13,IF(AND(AX12>=25%,AX12<65%),BA13,IF(AND(AX12>65%,AX12<=100%),BB13,IF(AX12>100%,BC13,""))))) -> Niveau d'endettement faible pour l'entreprise. Elle possède une bonne marge pour s'endetter davantage. | BI13: =IF('8. PROPOSITION'!M12="","",BG13) -> Niveau d'endettement faible pour l'entreprise. Elle possède une bonne marge pour s'endetter davantage.
B14: ='7. RISQUE'!B14 -> B. Historique de crédits et scoring de remboursement | C14: =IF('7. RISQUE'!$B$23="Veuillez noter tous les critères de risques !",0,'7. RISQUE'!H14) -> 4 | D14: 6 | E14: 5 | F14: 4 | G14: 3 | H14: 2 | I14: 1 | K14: Voyage ( Billet et hôtel) | L14: Très faible | M14: Manioc | AJ14: Riz | AK14: Soja | AL14: Sorgho | AO14: Ratio de consommation familiale 35% < R ≤ 65% | AQ14: Consommation familiale | AV14: ='5. RESULTAT'!K49 -> 450800000 | AX14: ='5. RESULTAT'!M49 -> 0.36581526 | AY14: <=35 | AZ14: >35<=65 | BB14: >75<=100 | BC14: >100
B15: ='7. RISQUE'!B15 -> C. Accès aux intrants | C15: =IF('7. RISQUE'!$B$23="Veuillez noter tous les critères de risques !",0,'7. RISQUE'!H15) -> 2 | D15: 6 | E15: 5 | F15: 4 | G15: 3 | H15: 2 | I15: 1 | K15: Frais bancaires | M15: Maraîchage | AJ15: Soja | AK15: Sorgho | AL15: Autre | AQ15: Revenus totaux | AV15: ='5. RESULTAT'!K50 -> 1232316000 | AY15: Le niveau de consommation du ménage de l'entrepreneur est très faible. Il faut rechercher les dépenses familiales cachées. | AZ15: Le niveau de consommation du ménage de l'entrepreneur est dans les normes. | BB15: Le niveau de consommation du ménage de l'entrepreneur est très élevé. Risque de détourner le crédit à des fins personnelles. | BC15: Niveau de consommation très élevé et dépasant l'ensemble des revenus de l'entrepreneur. Risque d'impayé très présent. | BF15: =IF('5. RESULTAT'!K29<0,"Le cumul des revenus de cet entrepreneur est négatif - Impossible de couvrir les dépenses familiales.",BG15) -> Le niveau de consommation du ménage de l'entrepreneur est dans les normes. | BG15: =IF(AX14<=35%,AY15,IF(AND(AX14>35%,AX14<=65%),AZ15,IF(AND(AX14>65%,AX14<=100%),BB15,IF(AX14>100%,BC15,"")))) -> Le niveau de consommation du ménage de l'entrepreneur est dans les normes. | BI15: =IF('8. PROPOSITION'!M12="","",BF15) -> Le niveau de consommation du ménage de l'entrepreneur est dans les normes.
B16: ='7. RISQUE'!B16 -> D. Accès et position dans le marché | C16: =IF('7. RISQUE'!$B$23="Veuillez noter tous les critères de risques !",0,'7. RISQUE'!H16) -> 3 | D16: 6 | E16: 5 | F16: 4 | G16: 3 | H16: 2 | I16: 1 | K16: Intérêts sur emprunts | M16: Niébé | AJ16: Sorgho | AK16: Autre | AO16: Ratio de dependance des autres revenus R ≤ 50% | AQ16: Autres revenus | AV16: ='5. RESULTAT'!K51 -> 454996000 | AX16: ='5. RESULTAT'!M51 -> 0.36922023 | AY16: <0 | AZ16: =0 -> 0 | BA16: >0<=50 | BB16: >50<100 | BC16: >100 | BI16: =IF('8. PROPOSITION'!M13="","",BF16)
B17: ='7. RISQUE'!B17 -> E. Qualité des actifs de l'entreprise/exploitation | C17: =IF('7. RISQUE'!$B$23="Veuillez noter tous les critères de risques !",0,'7. RISQUE'!H17) -> 3 | D17: 6 | E17: 5 | F17: 4 | G17: 3 | H17: 2 | I17: 1 | K17: Échéance autre crédit | M17: Palmier à huile | AJ17: Autre | AQ17: Revenus totaux | AV17: ='5. RESULTAT'!K52 -> 1232316000 | AY17: Le cumul des revenus de cet entrepreneur est négatif - L'excédent d'exploitation est déficitaire ou trop faible | AZ17: L'entrepreneur n'a pas d'autres sources de revenus. Aucune déclaration à cet effet. À vérifier | BA17: Ratio de dépendance aux autres revenus dans la norme. | BB17: L'entrepreneur dépend énormément des autres revenus. Vérifier la rentabilité de l'activité à financer. | BC17: Les autres revenus sont très importants dans la capacité financière du client. Vérifier la rentabilité réelle de l'activité. | BF17: =IF('5. RESULTAT'!K29<0,"Le cumul des revenus de cet entrepreneur est négatif - L'excédent d'exploitation est déficitaire ou trop faible.",BG17) -> Ratio de dépendance aux autres revenus dans la norme. | BG17: =IF(AX16<0%,AY17,IF(AX16=0%,AZ17,IF(AND(AX16>0%,AX16<=50%),BA17,IF(AND(AX16>50%,AX16<=100%),BB17,IF(AX16>100%,BC17,""))))) -> Ratio de dépendance aux autres revenus dans la norme. | BI17: =IF('8. PROPOSITION'!M12="","",BG17) -> Ratio de dépendance aux autres revenus dans la norme.
B18: ='7. RISQUE'!B18 -> F. Production et Exploitation | C18: =IF('7. RISQUE'!$B$23="Veuillez noter tous les critères de risques !",0,'7. RISQUE'!H18) -> 6 | D18: 6 | E18: 5 | F18: 4 | G18: 3 | H18: 2 | I18: 1 | K18: Impôts - Taxes et permis | M18: Riz
B19: ='7. RISQUE'!B19 -> G. Environnement | C19: =IF('7. RISQUE'!$B$23="Veuillez noter tous les critères de risques !",0,'7. RISQUE'!H19) -> 2 | D19: 6 | E19: 5 | F19: 4 | G19: 3 | H19: 2 | I19: 1 | K19: Réparation et maintenance | M19: Soja
B20: ='7. RISQUE'!B20 -> H. Capacité de remboursement, Solvabilité et niveau d'endettement | C20: =IF('7. RISQUE'!$B$23="Veuillez noter tous les critères de risques !",0,'7. RISQUE'!H20) -> 3 | D20: 6 | E20: 5 | F20: 4 | G20: 3 | H20: 2 | I20: 1 | K20: Amortissement | M20: Sorgho
E21: 5 | K21: Provisions | M21: Autre
K22: Prélèvement de l'exploitant
K23: Honoraires professionnels
K24: Eau, électricté, téléphone
K25: Autre
C32: FICHE D'ANALYSE DES DEMANDES DE CRÉDITS AGRICOLES
C36: Une proposition de Développement International Desjardins
C38: Adapatation (Guinée)
C39: Août_2022

Sheet PARAMETRAGE
A1: 1 | B1: L’emprunteur fait partie de l’élite des producteurs; il se démarque par ses capacités de gestionnaire et une bonne solidité financière. Il maîtrise bien ses outils de production et est en mesure de donner à l’agent de crédit une information pertinente dans les délais requis. Il respecte ses engagements personnels et financiers. Bien qu’il n’existe aucune situation où les risques de défaut sont nuls, cette catégorie d’emprunteurs pourra disposer de conditions de crédit et d’encadrement favorables. | C1: Fonds de roulement | F1: Cout de production | G1: Chiffre d'affaire | K1: Loyer | L1: Excellent | M1: Sous-sous-secteur d'activité | N1: A | O1: Alibori | P1: CONAKRY | Q1: BOKÉ | R1: KINDIA | S1: MAMOU | T1: LABÉ | U1: FARANAH | V1: KANKAN | W1: NZÉRÉKORÉ | AC1: AGRICULTURE | AD1: COMMERCE | AE1: ARTISANAT | AF1: SERVICE | AG1: INDUSTRIE | AH1: Autre | AI1: Production_animale | AJ1: Production_végétale | AK1: Transformation | AL1: Commercialisation | AM1: Autre | AO1: Ratios | AV1: ='5. RESULTAT'!K36 -> Calculs | AX1: ='5. RESULTAT'!M36 -> Résultats | AY1: Excellent | AZ1: Bon ratio | BA1: Passable | BB1: insuffisant | BC1: Médiocre | BF1: =CONCATENATE("Le crédit dépasse le besoin réel de ",(BF4),"%") -> Le crédit dépasse le besoin réel de -67,49% | CM1: Prélèvement | CN1: =IF('5. RESULTAT'!D16="Prélèvement de l'exploitant",'5. RESULTAT'!K16,0) -> 0 | CP1: Revenus nets issus d'autres activités commerciales | CS1: =IF('8. PROPOSITION'!M20="",0,CU1) -> 300000000 | CT1: ='8. PROPOSITION'!M12/'8. PROPOSITION'!M20 -> 100000000 | CU1: ='8. PROPOSITION'!M12+EH12 -> 300000000 | DY1: ='1. DEMANDE'!V50 -> 8 | DZ1: Mensuelle | EA1: Unique | EB1: Unique | EC1: Unique | ED1: Unique | EE1: Unique | EI1: Montant Prélevé provision | EJ1: Montant prélevé Amortissement
A2: 2 | B2: Il est évident que l’emprunteur ayant une cote de risque basse constitue aussi pour la compétition une cible de choix; l’agent de crédit devra donc éviter de négliger cette clientèle. Avec cette clientèle, l'agent de crédit devra être proactif et orienté sur le maintien d’une bonne relation d’affaires et le service-conseil. | C2: Achat d'intrants | E2: Production végétale | F2: ='.'!F2 -> 922680000 | G2: ='.'!G2 -> 1700000000 | K2: Salaires employés | L2: Très bien | M2: Agrumes | N2: B | O2: Atacora | P2: Conakry | Q2: Boffa | R2: Coyah | S2: Dalaba | T2: Koubia | U2: Dabola | V2: Kankan | W2: Beyla | AC2: Production_animale | AD2: Habillement | AE2: Menuiserie | AF2: Formation | AG2: Fabrication | AI2: Bovin | AJ2: Agrumes | AK2: Agrumes | AL2: Agrumes | AO2: Niveau de participation R ≤ 65 % | AQ2: Montant du crédit proposé | AV2: ='5. RESULTAT'!K37 -> 300000000 | AX2: ='5. RESULTAT'!M37 -> 0.32513981 | AY2: Excellent ratio. Le niveau de participation de financement est très faible. | AZ2: Bon ratio. Le niveau de participation de financement est acceptable. | BA2: Ratio passable. Le niveau de participation de financement est au seuil de la norme indiquée. | BB2: Le niveau de participation de financement dépasse la limite sugérée. | BC2: Attention, le niveau de participation de financement dépasse les dépenses prévues. | BE2: =IF('1. DEMANDE'!I54="Investissement",'3. BILAN'!J50,'3. BILAN'!J60) -> 922680000 | BF2: =IF('8. PROPOSITION'!M12>BE2,BF1,IF('8. PROPOSITION'!M12=BE2,"Le crédit couvre bien le besoin réel.","Attention, le crédit ne couvre pas le besoin réel.")) -> Attention, le crédit ne couvre pas le besoin réel. | BG2: =IF(AX2<=20%,AY2,IF(AND(AX2>20%,AX2<=50%),AZ2,IF(AND(AX2>50%,AX2<=65%),BA2,IF(AND(AX2>65%,AX2<=100%),BB2,IF(AX2>100%,BC2,""))))) -> Bon ratio. Le niveau de participation de financement est acceptable. | BH2: =CONCATENATE(BG2," ",BF2) -> Bon ratio. Le niveau de participation de financement est acceptable. Attention, le crédit ne couvre pas le besoin réel. | BI2: =IF('8. PROPOSITION'!M12="","",IF(BE2<0,"Attention ! Ce client n'a de besoin réel identifié - veuillez revoir les analyses",BH2)) -> Bon ratio. Le niveau de participation de financement est acceptable. Attention, le crédit ne couvre pas le besoin réel. | CM2: Prélèvement | CN2: =IF('5. RESULTAT'!D17="Prélèvement de l'exploitant",'5. RESULTAT'!K17,0) -> 0 | CP2: Salaires net (après déduction des engagements) | CS2: =IF('8. PROPOSITION'!M20="",0,EH12) -> 0 | DY2: =IF(DY1=1,"ONE",IF(DY1=2,"TWO",IF(DY1=3,"THREE",IF(DY1=4,"FOUR",IF(DY1=5,"FOUR",IF(AND(DY1>5,DY1<12),"FIVE",IF(DY1>11,"SIX",""))))))) -> FIVE | EA2: Mensuelle | EB2: Mensuelle | EC2: Mensuelle | ED2: Mensuelle | EE2: Mensuelle | EH2: Ligne 1 | EI2: =IF('5. RESULTAT'!D16="Provisions",'5. RESULTAT'!K16,0) -> 0 | EJ2: =IF('5. RESULTAT'!D16="Amortissement ",'5. RESULTAT'!K16,0) -> 0
A3: 3 | B3: L’emprunteur faisant partie de cette catégorie ne constitue pas un risque dans la mesure où il est bien encadré. Sa maîtrise des outils de production et de gestion est bonne mais pourrait être améliorée. Puisque la majorité des emprunteurs font partie de cette catégorie, l’agent de crédit doit user de son jugement, s’appuyer sur son expérience et faire preuve de discernement afin de bien conseiller cette clientèle et appuyer son développement. | C3: Achats de petits outillages | E3: Production animale | F3: ='.'!F3 -> 0 | G3: ='.'!G3 -> 0 | K3: Fourniture de bureau | L3: Bien | M3: Anacarde | N3: C | O3: Atlantique | Q3: Boké_ | R3: Dubréka | S3: Mamou | T3: Labé | U3: Dinguiraye | V3: Kérouane | W3: Guéckédou | AC3: Production_végétale | AD3: Restauration | AE3: Soudure | AF3: Assistance | AG3: Autre | AI3: Aquaculture | AJ3: Anacarde | AK3: Anacarde | AL3: Anacarde | AQ3: Total Dépenses d'exploitation | AV3: ='5. RESULTAT'!K38 -> 922680000 | AY3: <=20% | AZ3: >20 et <=50 | BA3: >50 et <=65 | BB3: >65 et <=100 | BC3: >100 | BF3: =(('8. PROPOSITION'!M12/BE2)-1)*100 -> -67.486019 | CM3: Prélèvement | CN3: =IF('5. RESULTAT'!D18="Prélèvement de l'exploitant",'5. RESULTAT'!K18,0) -> 0 | CP3: Prélèvement de l'exploitant | EA3: Bimestrielle | EB3: Bimestrielle | EC3: Bimestrielle | ED3: Bimestrielle | EE3: Bimestrielle | EH3: Ligne 2 | EI3: =IF('5. RESULTAT'!D17="Provisions",'5. RESULTAT'!K17,0) -> 0 | EJ3: =IF('5. RESULTAT'!D17="Amortissement ",'5. RESULTAT'!K17,0) -> 0
A4: 4 | B4: Il faut être prudent avec ce genre de client. Soit il est nouveau, soit il s’agir d’un emprunteur de longue date qui a connu une situation adverse avec qui il faut opérer un redressement ou d’un emprunteur qui est financièrement plus serré, mais qui démontre des aptitudes pour progresser. Bien que non obligatoire, le support d’un conseiller technique et/ou de gestion pourrait être suggéré. Appuyez-vous sur les commentaires relatifs aux Ratios de décision pour valider votre recommandation. | C4: Investissement | E4: Transformation | F4: ='.'!F4 -> 0 | G4: ='.'!G4 -> 0 | K4: Publicité et promotion | L4: Passable | M4: Ananas | N4: D | O4: Borgou | Q4: Fria | R4: Forécariah | S4: Pita | T4: Lélouma | U4: Faranah | V4: Kouroussa | W4: Lola | AC4: Transformation | AD4: Alimentation | AE4: Coiffure | AF4: Divers_Service | AI4: Aviculture | AJ4: Ananas | AK4: Ananas | AL4: Ananas | AO4: Couverture de l'échéance R ≥ 1,5 | AQ4: Capacité de remboursement | AV4: ='5. RESULTAT'!K39 -> 2.6050533e+08 | AX4: ='5. RESULTAT'!M39 -> 1.439256 | AY4: >4 | AZ4: <=4 et >=2 | BA4: <2 et >=1,5 | BB4: <1,5 et >=1 | BC4: <1 | BF4: =ROUNDUP(BF3,2) -> -67.49 | BI4: =IF('8. PROPOSITION'!M12="","",IF('5. RESULTAT'!K32<0,"Attention ! La capacité de remboursement est négative - veuillez échanger avec le client",BG5)) -> La couverture de l'échéance est acceptable mais trop juste. Le risque d'impayé est à prendre en compte. | CM4: Prélèvement | CN4: =IF('5. RESULTAT'!D19="Prélèvement de l'exploitant",'5. RESULTAT'!K19,0) -> 0 | CP4: Contribution d'autres personnes de la famille | EB4: Trimestrielle | EC4: Trimestrielle | ED4: Trimestrielle | EE4: Trimestrielle | EH4: Ligne 3 | EI4: =IF('5. RESULTAT'!D18="Provisions",'5. RESULTAT'!K18,0) -> 0 | EJ4: =IF('5. RESULTAT'!D18="Amortissement ",'5. RESULTAT'!K18,0) -> 0
A5: 5 | B5: En tant que professionnel, l’agent de crédit doit traiter tous les emprunteurs avec considération et professionnalisme. Avec les emprunteurs de cette catégorie, il devra donc considérer les demandes visant à améliorer la situation des emprunteurs tout en portant un suivi attentif à son dossier de crédit parce que celui-ci n’a pas une grande marge de manœuvre en cas de difficulté. Puisque les emprunteurs dans cette catégorie ne pourront obtenir des crédits importants, le rôle de l’agent de crédit sera donc de les conseiller afin qu’ils utilisent leur crédit judicieusement, qu’ils respectent leurs échéances et qu’ils améliorent leur maîtrise de la production. Ceci afin de pouvoir améliorer leur cote de risque et l’accès au financement. Les crédits devraient tous être adéquatement garantis et/ou avalisés. Pour un crédit agricole, toute autre mesure d’atténuation de risque telle que l’assurance agricole (si cela existe) devrait être obligatoire. | C5: Autre | E5: Commercialisation | F5: ='.'!F5 -> 0 | G5: ='.'!G5 -> 0 | K5: Téléphone / Internet | L5: Faible | M5: Aquaculture | N5: E | O5: Collines | Q5: Gaoual | R5: Kindia | T5: Mali | U5: Kissidougou | V5: Mandiana | W5: Macenta | AC5: Commercialisation | AD5: Cosmétique | AE5: Mécanique | AF5: Auto_école | AI5: Caprin | AJ5: Arachide | AK5: Arachide | AL5: Arachide | AQ5: Service de la dette | AV5: ='5. RESULTAT'!K40 -> 181000000 | AY5: Excellent ratio. La couverture de l'échéance ou de service de la dette est confortable. | AZ5: Bon ratio. La couverture de l'échéance ou de service de la dette est bonne. | BA5: Ratio acceptable. La couverture de l'échéance ou de service de la dette est rassurante. | BB5: La couverture de l'échéance est acceptable mais trop juste. Le risque d'impayé est à prendre en compte. | BC5: Ratio trop faible - L'échéance ou le service de la dette n'est pas couvert. Forte probabilité de défaut. | BG5: =IF(AX4>4,AY5,IF(AND(AX4<=4,AX4>=2),AZ5,IF(AND(AX4<2,AX4>=1.5),BA5,IF(AND(AX4<1.5,AX4>=1),BB5,IF(AX4<1,BC5,""))))) -> La couverture de l'échéance est acceptable mais trop juste. Le risque d'impayé est à prendre en compte. | BI5: =IF('5. RESULTAT'!K33<0,"Attention ! La capacité de rembourssement est négative - veuillez échanger avec le client",IF('8. PROPOSITION'!M13="","",BG6)) | CM5: Prélèvement | CN5: =IF('5. RESULTAT'!D20="Prélèvement de l'exploitant",'5. RESULTAT'!K20,0) -> 0 | CP5: Revenus nets issus de la location (biens immobiliers et/matériels) | CU5: ='5. RESULTAT'!K32/'8. PROPOSITION'!M20 -> 2.6050533e+08 | CV5: Montant disponible en tranche | EC5: Quadrimestre | ED5: Quadrimestre | EE5: Quadrimestre | EH5: Ligne 4 | EI5: =IF('5. RESULTAT'!D19="Provisions",'5. RESULTAT'!K19,0) -> 0 | EJ5: =IF('5. RESULTAT'!D19="Amortissement ",'5. RESULTAT'!K19,0) -> 0
A6: 6 | B6: L’emprunteur (client) : - n'a pas d'expérience avérée dans le domaine - a de fortes probabilités d’être en défaut à court terme; - n’a pas de marge de manœuvre; - emprunte au-delà de sa capacité de remboursement. - a un mauvais historique de crédit; - si ancien, a dans le passé, refusé certainement de collaborer afin de trouver des solutions à ses problèmes. Appuyez-vous sur les commentaires associés aux ratios de décision avant de valider le rejet de cette demande de crédit. | F6: ='.'!F6 -> 922680000 | G6: ='.'!G6 -> 1700000000 | K6: Communication | L6: Très faible | M6: Pêche | N6: F | O6: Couffo | Q6: Koundara | R6: Télimélé | T6: Tougué | W6: Nzérékoré | AD6: Mercerie | AE6: Maçonnerie | AF6: École_Collège | AI6: Ovin | AJ6: Coton | AK6: Coton | AL6: Igname | AO6: Ratio de fonds de roulement R ≥ 1,5 | AQ6: Actif à court terme | AV6: ='5. RESULTAT'!K41 -> 56000000 | AX6: ='5. RESULTAT'!M41 -> 2.8 | AY6: >4 | AZ6: <=4 et >=2 | BA6: <2 et >=1,5 | BB6: <1,5 et >=1 | BC6: <1 | BI6: =IF('8. PROPOSITION'!M12="","",BG7) -> Bon ratio. Les actifs à court terme surpassent les dettes à moins d'un an et dégagent un surplus important. | CM6: Prélèvement | CN6: =IF('5. RESULTAT'!D21="Prélèvement de l'exploitant",'5. RESULTAT'!K21,0) -> 0 | CP6: Autres sources de revenus | ED6: Semestrielle | EE6: Semestrielle | EH6: Ligne 5 | EI6: =IF('5. RESULTAT'!D20="Provisions",'5. RESULTAT'!K20,0) -> 0 | EJ6: =IF('5. RESULTAT'!D20="Amortissement ",'5. RESULTAT'!K20,0) -> 0
K7: Électricité | M7: Arachide | N7: G | O7: Donga | W7: Yomou | AD7: Vaisselle -Émaux | AE7: Cordonnerie | AF7: Autre | AI7: Pêche | AJ7: Igname | AK7: Igname | AL7: Maïs | AQ7: Passif à court terme | AV7: ='5. RESULTAT'!K42 -> 20000000 | AY7: Excellent ratio. Il existe un fonds de roulement conséquent permettant de faire tourner l'activité. | AZ7: Bon ratio. Les actifs à court terme surpassent les dettes à moins d'un an et dégagent un surplus important. | BA7: Bon ratio. Les actifs à court terme surpassent les dettes à moins d'un an et dégagent un surplus important. | BB7: Ratio passable. Les actifs à court terme surpassent légèrement les dettes à moins d'un an. Risque d'insuffisance du fonds de roulement. | BC7: Ratio trop faible - Fonds de roulement négatif. Nécessité de renforcer l'exploitation. | BG7: =IF(AX6>4,AY7,IF(AND(AX6<=4,AX6>=2),AZ7,IF(AND(AX6<2,AX6>=1.5),BA7,IF(AND(AX6<1.5,AX6>=1),BB7,IF(AX6<1,BC7,""))))) -> Bon ratio. Les actifs à court terme surpassent les dettes à moins d'un an et dégagent un surplus important. | BI7: =IF('5. RESULTAT'!K32<0,"Attention ! La capacité de remboursement est négative - veuillez échanger avec le client",IF('8. PROPOSITION'!M15="","",BG8)) | CM7: Prélèvement | CN7: =IF('5. RESULTAT'!D22="Prélèvement de l'exploitant",'5. RESULTAT'!K22,0) -> 0 | EE7: Annuelle | EH7: Ligne 6 | EI7: =IF('5. RESULTAT'!D21="Provisions",'5. RESULTAT'!K21,0) -> 0 | EJ7: =IF('5. RESULTAT'!D21="Amortissement ",'5. RESULTAT'!K21,0) -> 0
K8: Eau | L8: Nouveau Client | M8: Aviculture | N8: H | O8: Littoral | Q8: Boffa | R8: Boké_ | AD8: Autre | AE8: Coiffure | AI8: Pisciculture | AJ8: Maïs | AK8: Maïs | AL8: Mangue | AO8: Ratio de solvabilité R ≤ 0,5 | AQ8: Dettes totales | AV8: ='5. RESULTAT'!K43 -> 20000000 | AX8: ='5. RESULTAT'!M43 -> 0.017050298 | AY8: <0,1 | AZ8: >=0,1 et<=0,5 | BA8: >=0,1 et<=0,5 | BB8: >=0,5 et<=1 | BC8: >1 | CM8: Prélèvement | CN8: =IF('5. RESULTAT'!D23="Prélèvement de l'exploitant",'5. RESULTAT'!K23,0) -> 0 | EH8: Ligne 7 | EI8: =IF('5. RESULTAT'!D22="Provisions",'5. RESULTAT'!K22,0) -> 0 | EJ8: =IF('5. RESULTAT'!D22="Amortissement ",'5. RESULTAT'!K22,0) -> 0
K9: Assurances | L9: Excellent | M9: Coton | N9: I | O9: Mono | Q9: Boffa-Centre | R9: Boké-Centre | S9: Dabiss · Kamsar · Kanfarandé · Kolaboui · Malapouyah · Sangaredi · Sansalé · Tanéné | AE9: Autre | AI9: Autre | AJ9: Mangue | AK9: Mangue | AL9: Manioc | AQ9: Fonds propres | AV9: ='5. RESULTAT'!K44 -> 1173000000 | AY9: Excellent ratio de solvabilité. Les dettes de l'entreprise sont très faibles par rapport aux fonds propres | AZ9: La norme de solvabilité est respectée. Les dettes de l'entreprise sont faibles par rapport aux fonds propres | BB9: Les dettes de l'entreprise sont élevées et risquent de s'étendre vers le niveau des fonds propres avec un nouveau crédit. | BC9: Les dettes de l'entreprise sont très élevées et dépassent le niveau de fonds propres. L'entreprise n'est pas solvable. | BF9: =IF('3. BILAN'!I37<0,"Attention, les fonds propres sont négatifs. Il faut échanger avec le client.",PARAMETRAGE!BG9) -> Excellent ratio de solvabilité. Les dettes de l'entreprise sont très faibles par rapport aux fonds propres | BG9: =IF(AX8<0.1,AY9,IF(AND(AX8>=0.1,AX8<=0.5),AZ9,IF(AND(AX8>0.5,AX8<=1),BB9,IF(AX8>1,BC9,"")))) -> Excellent ratio de solvabilité. Les dettes de l'entreprise sont très faibles par rapport aux fonds propres | BI9: =IF('8. PROPOSITION'!M12="","",BF9) -> Excellent ratio de solvabilité. Les dettes de l'entreprise sont très faibles par rapport aux fonds propres | CM9: Prélèvement | CN9: =IF('5. RESULTAT'!D24="Prélèvement de l'exploitant",'5. RESULTAT'!K24,0) -> 0 | DZ9: ONE | EA9: TWO | EB9: THREE | EC9: FOUR | ED9: FIVE | EE9: SIX | EH9: Ligne 8 | EI9: =IF('5. RESULTAT'!D23="Provisions",'5. RESULTAT'!K23,0) -> 0 | EJ9: =IF('5. RESULTAT'!D23="Amortissement ",'5. RESULTAT'!K23,0) -> 0
K10: Frais de transport | L10: Très bien | M10: Bovin/Ovin/Caprin | O10: Ouémé | Q10: Colia | R10: Bintimodiya | S10: Dabiss · Kamsar · Kanfarandé · Kolaboui · Malapouyah · Sangaredi · Sansalé · Tanéné | AJ10: Manioc | AK10: Manioc | AL10: Maraîchage | AO10: Ratio de liquidité immédiate R ≥ 1 | AQ10: Trésorerie disponible | AV10: ='5. RESULTAT'!K45 -> 36000000 | AX10: ='5. RESULTAT'!M45 -> 1.8 | AY10: >4 | AZ10: <=4 et >=2 | BA10: <2 et >=1 | BB10: <1 et >=0,75 | BC10: <075 | CM10: Prélèvement | CN10: =IF('5. RESULTAT'!D25="Prélèvement de l'exploitant",'5. RESULTAT'!K25,0) -> 0 | EH10: Ligne 9 | EI10: =IF('5. RESULTAT'!D24="Provisions",'5. RESULTAT'!K24,0) -> 0 | EJ10: =IF('5. RESULTAT'!D24="Amortissement ",'5. RESULTAT'!K24,0) -> 0
K11: Entretien et réparation | L11: Bien | M11: Igname | O11: Plateau | Q11: Douprou | R11: Dabiss | S11: Dabiss · Kamsar · Kanfarandé · Kolaboui · Malapouyah · Sangaredi · Sansalé · Tanéné | AJ11: Maraîchage | AK11: Niébé | AL11: Niébé | AQ11: Passif à court terme | AV11: ='5. RESULTAT'!K46 -> 20000000 | AY11: Excellent ratio. Les "dettes à moins d'un an" peuvent être réglées facilement. | AZ11: Très bon ratio. La trésorerie et les créances sont assez importantes pour régler les dettes à moins d'un an. | BA11: Ratio respectant la norme. Les dettes à moins d'un an seront réglées. | BB11: Ratio ne respectant pas la norme. Des difficultés subsistent pour le règlement des dettes à moins d'un an. | BC11: Ratio hors norme. L'entreprise peut être en difficulté et doit compter sur la vente de ses stocks pour régler ses dettes à court terme. | BG11: =IF(AX10>4,AY11,IF(AND(AX10<=4,AX10>=2),AZ11,IF(AND(AX10<2,AX10>=1),BA11,IF(AND(AX10<1,AX10>=0.75),BB11,IF(AX10<0.75,BC11,""))))) -> Ratio respectant la norme. Les dettes à moins d'un an seront réglées. | BI11: =IF('8. PROPOSITION'!M12="","",BG11) -> Ratio respectant la norme. Les dettes à moins d'un an seront réglées. | CM11: Prélèvement | CN11: =IF('5. RESULTAT'!D26="Prélèvement de l'exploitant",'5. RESULTAT'!K26,0) -> 0 | EH11: Ligne 10 | EI11: ='5. RESULTAT'!D25 -> 0 | EJ11: =IF('5. RESULTAT'!D25="Amortissement ",'5. RESULTAT'!K25,0) -> 0
B12: Critères | C12: Cote de risque (1 à 6) | D12: Zone de risque maximun (proche de 6) | E12: Zone de risque maximun (proche de 6) | F12: Zone de risque maximun (proche de 6) | G12: Zone de risque maximun (proche de 6) | H12: Zone de risque maximun (proche de 6) | I12: Zone de risque maximun (proche de 6) | K12: Carburant | L12: Passable | M12: Maïs | O12: Zou | Q12: Koba-Tatema | R12: Kamsar | S12: Dabiss · Kamsar · Kanfarandé · Kolaboui · Malapouyah · Sangaredi · Sansalé · Tanéné | AJ12: Niébé | AK12: Palmier à huile | AL12: Pomme de terre | AO12: Ratio d'endettement R < 65 % | AQ12: Dettes totales + Crédit proposé | AV12: ='5. RESULTAT'!K47 -> 320000000 | AX12: ='5. RESULTAT'!M47 -> 0.21433356 | AY12: <10 | AZ12: >=10<25 | BA12: >=25<75 | BB12: >75<=100 | BC12: >100 | CM12: Total | CN12: =CN1+CN2+CN3+CN4+CN5+CN6+CN7+CN8+CN9+CN10+CN11 -> 0 | EH12: =EI12+EJ12 -> 0 | EI12: =EI2+EI3+EI4+EI5+EI6+EI7+EI8+EI9+EI10+EI11 -> 0 | EJ12: =EJ2+EJ3+EJ4+EJ5+EJ6+EJ7+EJ8+EJ9+EJ10+EJ11 -> 0
B13: ='7. RISQUE'!B13 -> A. Direction Compétences, expériences, qualité morale, stabilité sociale.. | C13: =IF('7. RISQUE'!$B$23="Veuillez noter tous les critères de risques !",0,'7. RISQUE'!H13) -> 1 | D13: 6 | E13: 5 | F13: 4 | G13: 3 | H13: 2 | I13: 1 | K13: Frais douane | L13: Faible | M13: Manguier | Q13: Lisso | R13: Kanfarandé | S13: Dabiss · Kamsar · Kanfarandé · Kolaboui · Malapouyah · Sangaredi · Sansalé · Tanéné | AJ13: Palmier à huile | AK13: Pomme de terre | AL13: Riz | AQ13: Actif total + Crédit proposé | AV13: ='5. RESULTAT'!K48 -> 1493000000 | AY13: Niveau d'endettement très faible pour l'entreprise. Elle peut profiter des crédits productifs pour sa croissance. | AZ13: Niveau d'endettement faible pour l'entreprise. Elle possède une bonne marge pour s'endetter davantage. | BA13: Niveau d'endettement acceptable. | BB13: Niveau d'endettement très élevé pour l'entreprise. | BC13: Surendettement de l'entreprise. Le nouveau crédit risque de plonger davantage l'entreprise | BG13: =IF(AX12<10%,AY13,IF(AND(AX12>=10%,AX12<25%),AZ13,IF(AND(AX12>=25%,AX12<65%),BA13,IF(AND(AX12>65%,AX12<=100%),BB13,IF(AX12>100%,BC13,""))))) -> Niveau d'endettement faible pour l'entreprise. Elle possède une bonne marge pour s'endetter davantage. | BI13: =IF('8. PROPOSITION'!M12="","",BG13) -> Niveau d'endettement faible pour l'entreprise. Elle possède une bonne marge pour s'endetter davantage.
B14: ='7. RISQUE'!B14 -> B. Historique de crédits et scoring de remboursement | C14: =IF('7. RISQUE'!$B$23="Veuillez noter tous les critères de risques !",0,'7. RISQUE'!H14) -> 4 | D14: 6 | E14: 5 | F14: 4 | G14: 3 | H14: 2 | I14: 1 | K14: Voyage ( Billet et hôtel) | L14: Très faible | M14: Manioc | Q14: Mankountan | R14: Kolaboui | S14: Dabiss · Kamsar · Kanfarandé · Kolaboui · Malapouyah · Sangaredi · Sansalé · Tanéné | AJ14: Pomme de terre | AK14: Riz | AL14: Soja | AO14: Ratio de consommation familiale 35% < R ≤ 65% | AQ14: Consommation familiale | AV14: ='5. RESULTAT'!K49 -> 450800000 | AX14: ='5. RESULTAT'!M49 -> 0.36581526 | AY14: <=35 | AZ14: >35<=65 | BB14: >75<=100 | BC14: >100
B15: ='7. RISQUE'!B15 -> C. Accès aux intrants | C15: =IF('7. RISQUE'!$B$23="Veuillez noter tous les critères de risques !",0,'7. RISQUE'!H15) -> 2 | D15: 6 | E15: 5 | F15: 4 | G15: 3 | H15: 2 | I15: 1 | K15: Frais bancaires | M15: Maraîchage | Q15: Tamita | R15: Malapouyah | S15: Dabiss · Kamsar · Kanfarandé · Kolaboui · Malapouyah · Sangaredi · Sansalé · Tanéné | AJ15: Riz | AK15: Soja | AL15: Sorgho | AQ15: Revenus totaux | AV15: ='5. RESULTAT'!K50 -> 1232316000 | AY15: Le niveau de consommation du ménage de l'entrepreneur est très faible. Il faut rechercher les dépenses familiales cachées. | AZ15: Le niveau de consommation du ménage de l'entrepreneur est dans les normes. | BB15: Le niveau de consommation du ménage de l'entrepreneur est très élevé. Risque de détourner le crédit à des fins personnelles. | BC15: Niveau de consommation très élevé et dépassant l'ensemble des revenus de l'entrepreneur. Risque d'impayé très élevé. | BF15: =IF(('5. RESULTAT'!K28+'4. BUDGET FAMILIAL'!K17)<0,"Le cumul des revenus de cet entrepreneur est négatif - Impossible de couvrir les dépenses familiales.",BG15) -> Le niveau de consommation du ménage de l'entrepreneur est dans les normes. | BG15: =IF(AX14<=35%,AY15,IF(AND(AX14>35%,AX14<=65%),AZ15,IF(AND(AX14>65%,AX14<=100%),BB15,IF(AX14>100%,BC15,"")))) -> Le niveau de consommation du ménage de l'entrepreneur est dans les normes. | BI15: =IF('8. PROPOSITION'!M12="","",BF15) -> Le niveau de consommation du ménage de l'entrepreneur est dans les normes.
B16: ='7. RISQUE'!B16 -> D. Accès et position dans le marché | C16: =IF('7. RISQUE'!$B$23="Veuillez noter tous les critères de risques !",0,'7. RISQUE'!H16) -> 3 | D16: 6 | E16: 5 | F16: 4 | G16: 3 | H16: 2 | I16: 1 | K16: Intérêts sur emprunts | M16: Niébé | Q16: Tougnifili | R16: Sangaredi | S16: Dabiss · Kamsar · Kanfarandé · Kolaboui · Malapouyah · Sangaredi · Sansalé · Tanéné | AJ16: Soja | AK16: Sorgho | AL16: Autre | AO16: Ratio de dependance des autres revenus R ≤ 50% | AQ16: Autres revenus | AV16: ='5. RESULTAT'!K51 -> 454996000 | AX16: ='5. RESULTAT'!M51 -> 0.36922023 | AY16: <0 | AZ16: =0 -> 0 | BA16: >0<=50 | BB16: >50<100 | BC16: >100 | BI16: =IF('8. PROPOSITION'!M13="","",BF16)
B17: ='7. RISQUE'!B17 -> E. Qualité des actifs de l'entreprise/exploitation | C17: =IF('7. RISQUE'!$B$23="Veuillez noter tous les critères de risques !",0,'7. RISQUE'!H17) -> 3 | D17: 6 | E17: 5 | F17: 4 | G17: 3 | H17: 2 | I17: 1 | K17: Redevance et autres | M17: Palmier à huile | R17: Sansalé | AJ17: Sorgho | AK17: Autre | AQ17: Revenus totaux | AV17: ='5. RESULTAT'!K52 -> 1232316000 | AY17: Attention ! Erreur ou le cumul des revenus de cet entrepreneur est négatif - L'excédent d'exploitation est déficitaire ou trop faible | AZ17: L'entrepreneur n'a pas d'autres sources de revenus. Aucune déclaration à cet effet. À vérifier | BA17: Ratio de dépendance aux autres revenus dans la norme. | BB17: L'entrepreneur dépend énormément des autres revenus. Vérifier la rentabilité de l'activité à financer. | BC17: Les autres revenus sont très importants dans la capacité financière du client. Vérifier la rentabilité réelle de l'activité. | BF17: =IF(('5. RESULTAT'!K28+'4. BUDGET FAMILIAL'!K17)<0,"Le cumul des revenus de cet entrepreneur est négatif - Le bénéfice d'exploitation est déficitaire.",BG17) -> Ratio de dépendance aux autres revenus dans la norme. | BG17: =IF(AX16<0%,AY17,IF(AX16=0%,AZ17,IF(AND(AX16>0%,AX16<=50%),BA17,IF(AND(AX16>50%,AX16<=100%),BB17,IF(AX16>100%,BC17,""))))) -> Ratio de dépendance aux autres revenus dans la norme. | BI17: =IF('8. PROPOSITION'!M12="","",BG17) -> Ratio de dépendance aux autres revenus dans la norme.
B18: ='7. RISQUE'!B18 -> F. Production et Exploitation | C18: =IF('7. RISQUE'!$B$23="Veuillez noter tous les critères de risques !",0,'7. RISQUE'!H18) -> 6 | D18: 6 | E18: 5 | F18: 4 | G18: 3 | H18: 2 | I18: 1 | K18: Impôts - Taxes et permis | M18: Riz | R18: Tanéné | AJ18: Autre
B19: ='7. RISQUE'!B19 -> G. Environnement | C19: =IF('7. RISQUE'!$B$23="Veuillez noter tous les critères de risques !",0,'7. RISQUE'!H19) -> 2 | D19: 6 | E19: 5 | F19: 4 | G19: 3 | H19: 2 | I19: 1 | K19: Réparation et maintenance | M19: Soja
B20: ='7. RISQUE'!B20 -> H. Capacité de remboursement, Solvabilité et niveau d'endettement | C20: =IF('7. RISQUE'!$B$23="Veuillez noter tous les critères de risques !",0,'7. RISQUE'!H20) -> 3 | D20: 6 | E20: 5 | F20: 4 | G20: 3 | H20: 2 | I20: 1 | K20: Amortissement | M20: Sorgho
K21: Provisions | M21: Autre
K22: Prélèvement de l'exploitant
K23: Honoraires professionnels
K24: Eau, électricité, téléphone | M24: Pôle A | N24: Riz, banane, ananas, agrume, légumes, palmier à huile, pêche, élevage, Taro. (Zone : Conakry, Forécariah, Dubréka, Boffa).
K25: Autre | M25: Pôle B | N25: Riz, culture fruitières, Maraichage, Manioc, Patate douce, Bovins. (Zone : Kindia, Mamou, Dalaba).
M26: Pôle C | N26: Mais, Pomme de terre, Culture fruitière, Maraichage, Fonio, arachide, Elevage, Taro. (Zone : Pita, Labé, Mali, Koubia, Tougé, Lélouma).
M27: Pôle D | N27: Riz, élevage bovins, arachide, coton, anacarde. (Zone : Boké, Télimelé, Koundara, Gaoual, Fria).
M28: Pôle E | N28: Riz, arachide, élevage bovin, caprin, niébé, maïs, fonio, sorgho, mil. (Zone : Faranah, Dabola, Dinguiraye).
M29: Pôle F | N29: Riz, mais, igname, manioc, coton, mangue, cultures maraichères, sorgho, mil. (Zones : Kankan, Kouroussa, Siguiri, Mandiana).
M30: Pôle G | N30: Riz palmier à huile, hévéa, café, cacao, banane, thé, élevage porcin. (Zone : Kissidougou, Guéckédou, Macenta).
M31: Pôle H | N31: Riz, élevage bovin, maïs, légumes, manioc, banane plantin, niébé, cola. (Zone : Kérouané, Beyla, Lola).
M32: Pôle I | N32: Riz, maïs, palmier à huile, hévéa, élevage porcin, manioc. (Zone : Nzérékoré, Yomou).

Sheet GRILLE

Sheet 1. DEMANDE
J3: =IF(G30="","DEMANDE DE CRÉDIT AGRICOLE",IF(G30<>"AGRICULTURE","DEMANDE DE CRÉDIT","DEMANDE DE CRÉDIT AGRICOLE")) -> DEMANDE DE CRÉDIT AGRICOLE
Z5: Agence de : | AD5: FORECARIAH
C7: Date de la demande : | I7: 23 | J7: / | K7: 12 | L7: / | M7: 2025 | Y7: Agent de crédit : | AD7: MOHAMED MMAH CAMARA
C9: Catégorie de clientèle : | I9: Individuel | O9: =IF(I9="","Type de Gpe/Grmt",IF(I9="Groupe","Type de Groupe",IF(I9="Groupement","Type de Grpment",""))) | Y9: =IF(I9="","Nombre de personnes",IF(OR(I9="Groupe",I9="Groupement"),"Nombre de personnes","")) | AH9: =IF(I9="","F",IF(OR(I9="Groupe",I9="Groupement"),"F","")) | AK9: =IF(I9="","H",IF(OR(I9="Groupe",I9="Groupement"),"H",""))
O11: =IF(I9="","Nom du Gpe/Grmt",IF(I9="Groupe","Nom du Groupe",IF(I9="Groupement","Nom du Grpment",""))) | AF11: =IF(I9="","Numéro :",IF(OR(I9="Groupe",I9="Groupement"),"Numéro :",""))
B13: 1. | C13: INFORMATIONS SUR LE MEMBRE/CLIENT
C15: Nom et Prénoms : | H15: MARIAMA KABA | AB15: Numéro/membre : | AH15: 10300181501
H16: (Suivant l'ordre de la pièce d’identité )
C17: Type de pièce d'identité : | J17: Carte d'Identité Biométrique | T17: Référence : | Y17: 2.2010125e+15
C19: Date et lieu de naissance : | J19: 1 | K19: / | L19: 1 | M19: / | N19: 1990 | P19: à | Q19: MAFERINYAH | Y19: Genre : | AA19: Femme
C21: Situation matrimoniale : | I21: Marié (e) | O21: Nombre de personnes à charge : | Y21: 7 | AA21: Nombre d'enfants scolarisés : | AJ21: 3
C23: Adresse de domicile et Contact : | K23: PLANTEUSE A MAFERINYAH CENTRE SECTEUR OLYMPIA TEL:623597829
O24: (Quartier, maison, lot et numéro de téléphone)
C25: Nombre d'années à l'adresse : | K25: 10 | P25: Type de propriété : | V25: Propriétaire
B28: 2. | C28: ACTIVITÉS
C30: Type d'activité : | G30: AGRICULTURE | M30: Sous-activité : | R30: Production_végétale | Z30: =IF(G30="","Sous-sous-activité (filière) :",IF(G30="AGRICULTURE","Sous-sous-activité (filière) :","Sous-sous-activité :")) -> Sous-sous-activité (filière) : | AG30: Ananas
C32: Description de l'activité : | J32: ACHAT D'UNE MACHINE ET INTRANTS AGRICOLE POUR LA REALISATION DE LA CULTURE D'ANANAS
C34: Nombre d'années dans l'activité : | L34: 5 | P34: Adresse du lieu d'activité : | X34: REALISATION DE LA CULTURE D'ANANAS A TAMBAYAH ET CONTA
C35: (Depuis combien de temps vous exercez cette activité ?)
C37: =IF(G30="","Superficie disponible :",IF(R30="Production_végétale","Superficie disponible :",IF(R30="Production_animale","Nombre de têtes :",""))) -> Superficie disponible : | I37: 2 | K37: =IF(G30="","Hectares",IF(R30="Production_végétale","Hectares","")) -> Hectares | P37: Région administrative : | W37: KINDIA | AC37: Préfecture : | AG37: Forécariah
C39: =IF(G30="","Superficie emblavée :",IF(R30="Production_végétale","Superficie emblavée :","")) -> Superficie emblavée : | I39: 2 | K39: =IF(G30="","Hectares",IF(R30="Production_végétale","Hectares","")) -> Hectares | P39: Pôle de développement agricole (PDA) : | AA39: A | AD39: Village : | AG39: TAMBAYAH ET CONTA
C43: Autres activités : | G43: COMMERCE DE RIZ DU PAYS | Y43: =IF(AA39="A",PARAMETRAGE!N24,IF('1. DEMANDE'!AA39="B",PARAMETRAGE!N25,IF('1. DEMANDE'!AA39="C",PARAMETRAGE!N26,IF('1. DEMANDE'!AA39="D",PARAMETRAGE!N27,IF('1. DEMANDE'!AA39="E",PARAMETRAGE!N28,IF('1. DEMANDE'!AA39="F",PARAMETRAGE!N29,IF('1. DEMANDE'!AA39="G",PARAMETRAGE!N30,IF('1. DEMANDE'!AA39="H",PARAMETRAGE!N31,IF('1. DEMANDE'!AA39="I",PARAMETRAGE!N32,""))))))))) -> Riz, banane, ananas, agrume, légumes, palmier à huile, pêche, élevage, Taro. (Zone : Conakry, Forécariah, Dubréka, Boffa).
C45: Lieu de l'activité : | G45: KABACK ET KAKOSSA
B48: 3. | C48: MODALITÉS DE LA DEMANDE
C50: Montant demandé : | H50: 300000000 | M50: GNF | P50: Durée demandée : | V50: 8 | X50: Mois | Z50: Périodicité de remboursement : | AI50: Mensuelle
C52: Taux d'intérêts : | G52: 0.03 | K52: Période de différé : | Q52: 5 | S52: Mois | U52: Nombre d'échéance : | AA52: 3 | AC52: Échéance : | AH52: 363000000
AH53: (Montant en GNF)
C54: Objet du crédit sollicité : | I54: Investissement | T54: Détail de l'objet de crédit : | AA54: ACHAT D'UN TRACTEUR ET INTRANTS AGRICOLES POUR LA REALISATION DE LA CULTURE D'ANANAS A TAMBAYAH ET CONTA
C56: Nouveau crédit : | I56: Renouvellement : | O56: X | Q56: Rang de crédit : | V56: 2
B59: 4. | C59: GARANTIES PROPOSÉES
C61: Type de Garantie | J61: Nature / Description des garanties | Z61: Valeur de la garantie | AG61: Valeur d'emprunt
C62: Caution solidaire | J62: 3 PERSONNES CAUTIONS
C63: Dépôt à terme
C64: Suretés réelles | J64: ATTESTATION DE CESSION ET PLAN DE MASSE( 1ha/2) | Z64: 810000000 | AG64: 648000000
C65: Autre garantie | J65: ACTE AUTHENTIQUE CONVENTION D'HYPOTHEQUE
C66: Total | AG66: =AG62+AG63+AG64+AG65 -> 648000000

Sheet 2. PROD
B2: AGENCE :
B3: Nom et Prénoms du client : | C3: ='1. DEMANDE'!H15 -> MARIAMA KABA | G3: N° Membre : | H3: ='1. DEMANDE'!AH15 -> 10300181501
B5: Date d'évaluation : | C5: 46093
B7: PÉRIODE DE LA CAMPAGNE AGRICOLE : | D7: 46127 | E7: Au : | F7: 46614
B9: Campagne | C9: Culture 1 | D9: Culture 2 | E9: Culture 3 | F9: Culture 4 | G9: Culture 5 | H9: Culture 6 | I9: TOTAL
B10: Type de culture | C10: ANANAS
B11: Surface cultivée en ha | C11: 2 | I11: =C11+D11+E11+F11+G11+H11 -> 2
B12: ÉLÉMENTS
B16: COÛT DE PRODUCTION (GNF) | C16: 922680000 | I16: =D16+E16+F16+G16+H16+C16 -> 922680000
B24: CHIFFRE D'AFFAIRES (GNF) | C24: 1700000000 | I24: =C24+D24+E24+F24+G24+H24 -> 1700000000
B25: Marge brute totale sur production (GNF) | C25: =C24-C16 -> 777320000 | D25: =D24-D16 -> 0 | E25: =E24-E16 -> 0 | F25: =F24-F16 -> 0 | G25: =G24-G16 -> 0 | H25: =H24-H16 -> 0 | I25: =C25+D25+E25+F25+G25+H25 -> 777320000
B27: Évaluation de l'apport personnel en main d'œuvre (force de travail personnel et familial) | C27: 220440000 | I27: =C27+D27+E27+F27+G27+H27 -> 220440000
B28: Besoins en crédit exprimés pour la production | C28: 300000000 | I28: =C28+D28+E28+F28+G28+H28 -> 300000000

Sheet 3. BILAN
B2: Nom et Prénoms du membre : | D2: ='1. DEMANDE'!H15 -> MARIAMA KABA | J2: Agence de : | K2: ='1. DEMANDE'!AD5 -> FORECARIAH
B4: Numéro client /membre : | D4: ='1. DEMANDE'!AH15 -> 10300181501 | H4: Agent de crédit : | J4: ='1. DEMANDE'!AD7 -> MOHAMED MMAH CAMARA
I6: Date d'évaluation : | J6: ='2. PROD'!C5 -> 46093
B8: 5. | C8: BILAN RECONSTITUE
C10: Éléments du bilan | I10: Actuel (N) | J10: Précédent (N-1) | K10: Commentaires
B13: 1 | C13: Encaisse / Compte épargne IMF/ Banque | I13: 30000000 | J13: 15000000
B14: 2 | C14: =IF('1. DEMANDE'!G30="","Inventaires (stocks de produits /intrants/etc.)",IF('1. DEMANDE'!G30="AGRICULTURE","Inventaires (stocks de produits /intrants/etc.)","Inventaires (stocks de marchandises/produits, etc.)")) -> Inventaires (stocks de produits /intrants/etc.) | I14: 20000000 | J14: 10000000
B15: 3 | C15: Clients (ventes à crédit)
B16: 4 | C16: Autres comptes à recevoir | I16: 6000000 | J16: 3000000
B17: 5 | C17: Actif à court terme (1+2+3+4) | I17: =SUM(I13:I16) -> 56000000 | J17: =SUM(J13:J16) -> 28000000
